Workbook

Sheet world_happiness_combined
A1: Original | B1: https://www.kaggle.com/datasets/yadiraespinoza/world-happiness-2015-2024
A2: Ranking | B2: Country | C2: Regional indicator | D2: Happiness score | E2: GDP per capita | F2: Social support | G2: Healthy life expectancy | H2: Freedom to make life choices | I2: Generosity | J2: Perceptions of corruption | K2: Year
A3: 1 | B3: Switzerland | C3: Western Europe | D3: 758700 | E3: 826132 | F3: 96240 | G3: 73 | H3: 99379 | I3: 37289 | J3: 23941 | K3: 2015
A4: 2 | B4: Iceland | C4: Western Europe | D4: 756100 | E4: 770416 | F4: 100000 | G4: 73 | H4: 93884 | I4: 54819 | J4: 74371 | K4: 2015
A5: 3 | B5: Denmark | C5: Western Europe | D5: 752700 | E5: 784114 | F5: 97030 | G5: 70 | H5: 96962 | I5: 42894 | J5: 12382 | K5: 2015
A6: 4 | B6: Norway | C6: Western Europe | D6: 752200 | E6: 863100 | F6: 94917 | G6: 71 | H6: 100000 | I6: 43598 | J6: 33860 | K6: 2015
A7: 5 | B7: Canada | C7: North America and ANZ | D7: 742700 | E7: 784595 | F7: 94322 | G7: 71 | H7: 94511 | I7: 57560 | J7: 40285 | K7: 2015
A8: 6 | B8: Finland | C8: Western Europe | D8: 740600 | E8: 763273 | F8: 94012 | G8: 71 | H8: 95813 | I8: 29339 | J8: 25039 | K8: 2015
A9: 7 | B9: Netherlands | C9: Western Europe | D9: 737800 | E9: 786460 | F9: 91295 | G9: 71 | H9: 91942 | I9: 59821 | J9: 42357 | K9: 2015
A10: 8 | B10: Sweden | C10: Western Europe | D10: 736400 | E10: 787799 | F10: 91930 | G10: 72 | H10: 98517 | I10: 45562 | J10: 20560 | K10: 2015
A11: 9 | B11: New Zealand | C11: North America and ANZ | D11: 728600 | E11: 739573 | F11: 94112 | G11: 72 | H11: 95468 | I11: 59683 | J11: 22231 | K11: 2015
A12: 10 | B12: Australia | C12: North America and ANZ | D12: 728400 | E12: 788909 | F12: 93368 | G12: 72 | H12: 97239 | I12: 54734 | J12: 35431 | K12: 2015
A13: 11 | B13: Israel | C13: Middle East and North Africa | D13: 727800 | E13: 726786 | F13: 87285 | G13: 72 | H13: 61695 | I13: 41679 | J13: 85894 | K13: 2015
A14: 12 | B14: Costa Rica | C14: Latin America and Caribbean | D14: 722600 | E14: 565412 | F14: 88279 | G14: 70 | H14: 94629 | I14: 32036 | J14: 80826 | K14: 2015
... A396: 56 | B396: Moldova | C396: Central and Eastern Europe | D396: 583800 | E396: 389611 | F396: 77725 | G396: 64 | H396: 36571 | I396: 24912 | J396: 2173 | K396: 2017
A397: 87 | B397: Greece | D397: 522700 | E397: 689283 | F397: 76955 | G397: 71 | H397: 14543 | I397: 0 | J397: 9324 | K397: 2017
A398: 74 | B398: Jordan | C398: Middle East and North Africa | D398: 533600 | E398: 529736 | F398: 76935 | G398: 65 | H398: 63566 | I398: 20544 | J398: 25803 | K398: 2017
A399: 83 | B399: Montenegro | C399: Central and Eastern Europe | D399: 523700 | E399: 599289 | F399: 76890 | G399: 67 | H399: 29622 | I399: 23615 | J399: 18990 | K399: 2017
A400: 126 | B400: Congo (Kinshasa) | C400: Sub-Saharan Africa | D400: 428000 | E400: 49232 | F400: 76310 | G400: 53 | H400: 35847 | I400: 29407 | J400: 12974 | K400: 2017
A401: 58 | B401: Bolivia | C401: Latin America and Caribbean | D401: 582300 | E401: 445677 | F401: 76222 | G401: 61 | H401: 84882 | I401: 26914 | J401: 13025 | K401: 2017
A402: 142 | B402: Botswana | C402: Sub-Saharan Africa | D402: 376600 | E402: 599805 | F402: 75846 | G402: 57 | H402: 76749 | I402: 11854 | J402: 21232 | K402: 2017
A403: 63 | B403: Peru | C403: Latin America and Caribbean | D403: 571500 | E403: 553370 | F403: 75673 | G403: 66 | H403: 68364 | I403: 15132 | J403: 10133 | K403: 2017
A404: 95 | B404: Nigeria | C404: Sub-Saharan Africa | D404: 507400 | E404: 418949 | F404: 75487 | G404: 49 | H404: 60001 | I404: 27557 | J404: 5626 | K404: 2017
A405: 130 | B405: Sudan | C405: Western Europe | D405: 413900 | E405: 352538 | F405: 75377 | G405: 56 | H405: 2278 | I405: 21754 | J405: 19351 | K405: 2017
A406: 25 | B406: Mexico | C406: Latin America and Caribbean | D406: 657800 | E406: 616423 | F406: 75182 | G406: 68 | H406: 62701 | I406: 14437 | J406: 28596 | K406: 2017
A407: 64 | B407: Mauritius | C407: Sub-Saharan Africa | D407: 562900 | E407: 635780 | F407: 75101 | G407: 66 | H407: 74629 | I407: 43067 | J407: 9085 | K407: 2017
A408: 92 | B408: Macedonia | C408: Central and Eastern Europe | D408: 517500 | E408: 569060 | F408: 74998 | G408: 66 | H408: 49511 | I408: 30279 | J408: 12982 | K408: 2017
A409: 139 | B409: Lesotho | C409: Sub-Saharan Africa | D409: 380800 | E409: 278507 | F409: 73893 | G409: 47 | H409: 59349 | I409: 18793 | J409: 25650 | K409: 2017
... A675: 48 | B675: Romania | C675: Central and Eastern Europe | D675: 606970 | E675: 689896 | F675: 75848 | G675: 73 | H675: 73214 | I675: 14604 | J675: 1056 | K675: 2019
A676: 49 | B676: Cyprus | D676: 604580 | E676: 750051 | F676: 75329 | G676: 77 | H676: 64287 | I676: 33664 | J676: 8973 | K676: 2019
A677: 50 | B677: Ecuador | C677: Latin America and Caribbean | D677: 602760 | E677: 541414 | F677: 80812 | G677: 74 | H677: 78813 | I677: 22310 | J677: 19277 | K677: 2019
A678: 51 | B678: Kuwait | C678: Middle East and North Africa | D678: 602070 | E678: 890841 | F678: 81230 | G678: 73 | H678: 78065 | I678: 25036 | J678: 21516 | K678: 2019
A679: 52 | B679: Thailand | C679: Southeast Asia | D679: 600800 | E679: 623303 | F679: 86769 | G679: 73 | H679: 88265 | I679: 63442 | J679: 6184 | K679: 2019
A680: 53 | B680: Latvia | C680: Western Europe | D680: 593970 | E680: 704728 | F680: 90211 | G680: 73 | H680: 41886 | I680: 13241 | J680: 14108 | K680: 2019
A681: 54 | B681: South Korea | C681: East Asia | D681: 589470 | E681: 772522 | F681: 75089 | G681: 77 | H681: 25236 | I681: 30875 | J681: 12378 | K681: 2019
A682: 55 | B682: Estonia | C682: Western Europe | D682: 589350 | E682: 734417 | F682: 94099 | G682: 74 | H682: 78441 | I682: 18213 | J682: 35525 | K682: 2019
A683: 56 | B683: Jamaica | C683: Latin America and Caribbean | D683: 588980 | E683: 493592 | F683: 91008 | G683: 73 | H683: 77563 | I683: 18897 | J683: 6239 | K683: 2019
A684: 57 | B684: Mauritius | C684: Sub-Saharan Africa | D684: 588820 | E684: 664941 | F684: 86328 | G684: 72 | H684: 78911 | I684: 38051 | J684: 13150 | K684: 2019
A685: 58 | B685: Japan | C685: East Asia | D685: 588610 | E685: 787667 | F685: 87371 | G685: 78 | H685: 70489 | I685: 12169 | J685: 30974 | K685: 2019
A686: 59 | B686: Honduras | C686: Latin America and Caribbean | D686: 586040 | E686: 381447 | F686: 76135 | G686: 73 | H686: 80340 | I686: 43420 | J686: 17303 | K686: 2019
...

Sheet Cleaned Data 2020 - 2024
A1: Ranking | B1: Country | C1: Regional indicator | D1: Happiness score | E1: GDP per capita | F1: Social support | G1: Healthy life expectancy | H1: Freedom to make life choices | I1: Generosity | J1: Perceptions of corruption | K1: Year | L1: Business Indicator
A2: 1 | B2: Finland | C2: Western Europe | D2: 780870 | E2: 836344 | F2: 96896 | G2: 72 | H2: 95535 | I2: 28022 | J2: 10373 | K2: 2020 | L2: =AVERAGE(E2,F2,H2,) -> 257193.75
A3: 2 | B3: Denmark | C3: Western Europe | D3: 764560 | E3: 863519 | F3: 97149 | G3: 72 | H3: 95928 | I3: 42609 | J3: 7109 | K3: 2020 | L3: =AVERAGE(E3,F3,H3,) -> 264149
A4: 3 | B4: Switzerland | C4: Western Europe | D4: 755990 | E4: 905054 | F4: 95143 | G4: 74 | H4: 90723 | I4: 47218 | J4: 23486 | K4: 2020 | L4: =AVERAGE(E4,F4,H4,) -> 272730
A5: 4 | B5: Iceland | C5: Western Europe | D5: 750450 | E5: 863228 | F5: 100000 | G5: 73 | H5: 95487 | I5: 63587 | J5: 72890 | K5: 2020 | L5: =AVERAGE(E5,F5,H5,) -> 264678.75
A6: 5 | B6: Norway | C6: Western Europe | D6: 748800 | E6: 926810 | F6: 96614 | G6: 73 | H6: 96672 | I6: 50540 | J6: 18580 | K6: 2020 | L6: =AVERAGE(E6,F6,H6,) -> 280024
A7: 6 | B7: Netherlands | C7: Western Europe | D7: 744890 | E7: 871326 | F7: 94577 | G7: 72 | H7: 88512 | I7: 59022 | J7: 30871 | K7: 2020 | L7: =AVERAGE(E7,F7,H7,) -> 263603.75
A8: 7 | B8: Sweden | C8: Western Europe | D8: 735350 | E8: 860451 | F8: 92619 | G8: 73 | H8: 93801 | I8: 47880 | J8: 17086 | K8: 2020 | L8: =AVERAGE(E8,F8,H8,) -> 261717.75
A9: 8 | B9: New Zealand | C9: North America and ANZ | D9: 729960 | E9: 808445 | F9: 96100 | G9: 73 | H9: 93295 | I9: 57164 | J9: 13484 | K9: 2020 | L9: =AVERAGE(E9,F9,H9,) -> 249460
A10: 9 | B10: Austria | C10: Western Europe | D10: 729420 | E10: 857230 | F10: 92884 | G10: 73 | H10: 87032 | I10: 44841 | J10: 47248 | K10: 2020 | L10: =AVERAGE(E10,F10,H10,) -> 259286.5
A11: 10 | B11: Luxembourg | C11: Western Europe | D11: 723750 | E11: 1000000 | F11: 89659 | G11: 73 | H11: 88009 | I11: 34389 | J11: 31158 | K11: 2020 | L11: =AVERAGE(E11,F11,H11,) -> 294417
A12: 11 | B12: Canada | C12: North America and ANZ | D12: 723210 | E12: 847054 | F12: 92751 | G12: 74 | H12: 92897 | I12: 49407 | J12: 34035 | K12: 2020 | L12: =AVERAGE(E12,F12,H12,) -> 258175.5
A13: 12 | B13: Australia | C13: North America and ANZ | D13: 722280 | E13: 852747 | F13: 95450 | G13: 74 | H13: 89702 | I13: 57032 | J13: 36980 | K13: 2020 | L13: =AVERAGE(E13,F13,H13,) -> 259474.75
... A347: 46 | B347: Mexico | C347: Latin America and Caribbean | D347: 612760 | E347: 702240 | F347: 67101 | G347: 75 | H347: 83965 | I347: 19635 | J347: 19636 | K347: 2022 | L347: =AVERAGE(E347,F347,H347,) -> 213326.5
A348: 47 | B348: Croatia | C348: Central and Eastern Europe | D348: 612520 | E348: 771867 | F348: 89648 | G348: 78 | H348: 72241 | I348: 23325 | J348: =AVERAGE(J79,J213,J645) -> 68380 | K348: 2022 | L348: =AVERAGE(E348,F348,H348,) -> 233439
A349: 48 | B349: Poland | C349: Central and Eastern Europe | D349: 612280 | E349: 795468 | F349: 88914 | G349: 78 | H349: 70671 | I349: 26538 | J349: 23877 | K349: 2022 | L349: =AVERAGE(E349,F349,H349,) -> 238763.25
A350: 49 | B350: El Salvador | C350: Latin America and Caribbean | D350: 612000 | E350: 572506 | F350: 58176 | G350: 75 | H350: 89984 | I350: 18951 | J350: 36099 | K350: 2022 | L350: =AVERAGE(E350,F350,H350,) -> 180166.5
A351: 50 | B351: Kuwait | C351: Middle East and North Africa | D351: 610610 | E351: 861713 | F351: 74496 | G351: 79 | H351: 83419 | I351: 18583 | J351: 24989 | K351: 2022 | L351: =AVERAGE(E351,F351,H351,) -> 254907
A352: 51 | B352: Hungary | C352: Central and Eastern Europe | D352: 608590 | E352: 791093 | F352: 93384 | G352: 76 | H352: 65489 | I352: 16603 | J352: 10886 | K352: 2022 | L352: =AVERAGE(E352,F352,H352,) -> 237491.5
A353: 52 | B353: Mauritius | C353: Sub-Saharan Africa | D353: 607110 | E353: 720156 | F353: 84581 | G353: 73 | H353: 79651 | I353: 27965 | J353: 18227 | K353: 2022 | L353: =AVERAGE(E353,F353,H353,) -> 221097
A354: 53 | B354: Uzbekistan | C354: Commonwealth of Independent States | D354: 606270 | E354: 551801 | F354: 82699 | G354: 74 | H354: 96707 | I354: 60507 | J354: 40970 | K354: 2022 | L354: =AVERAGE(E354,F354,H354,) -> 182801.75
A355: 54 | B355: Japan | C355: East Asia | D355: 603890 | E355: 830320 | F355: 82532 | G355: 82 | H355: 72502 | I355: 1532 | J355: 37182 | K355: 2022 | L355: =AVERAGE(E355,F355,H355,) -> 246338.5
A356: 55 | B356: Honduras | C356: Latin America and Caribbean | D356: 602210 | E356: 502979 | F356: 67050 | G356: 73 | H356: 78665 | I356: 43168 | J356: 13034 | K356: 2022 | L356: =AVERAGE(E356,F356,H356,) -> 162173.5
A357: 56 | B357: Portugal | C357: Western Europe | D357: 601630 | E357: 796549 | F357: 81707 | G357: 80 | H357: 88467 | I357: 3490 | J357: 6674 | K357: 2022 | L357: =AVERAGE(E357,F357,H357,) -> 241680.75
A358: 57 | B358: Argentina | C358: Latin America and Caribbean | D358: 596700 | E358: 720403 | F358: 83488 | G358: 76 | H358: 75047 | I358: 17207 | J358: 14472 | K358: 2022 | L358: =AVERAGE(E358,F358,H358,) -> 219734.5
A359: 58 | B359: Greece | C359: Middle East and North Africa | D359: 594820 | E359: 770827 | F359: 74276 | G359: 80 | H359: 33669 | I359: 3189 | J359: 18461 | K359: 2022 | L359: =AVERAGE(E359,F359,H359,) -> 219693
A360: 59 | B360: South Korea | C360: East Asia | D360: 593510 | E360: 837826 | F360: 67108 | G360: 82 | H360: 55924 | I360: 23723 | J360: 30003 | K360: 2022 | L360: =AVERAGE(E360,F360,H360,) -> 240214.5
... A646: 63 | B646: Greece | C646: Middle East and North Africa | D646: 593360 | E646: 786686 | F646: 78940 | G646: 76 | H646: 39053 | I646: 4532 | J646: 16097 | K646: 2024 | L646: =AVERAGE(E646,F646,H646,) -> 226169.75
A647: 64 | B647: Bosnia and Herzegovina | C647: Central and Eastern Europe | D647: 587700 | E647: 684293 | F647: 81541 | G647: 73 | H647: 71889 | I647: 61470 | J647: =AVERAGE(J70,J217,J368,J517) -> 74573.75 | K647: 2024 | L647: =AVERAGE(E647,F647,H647,) -> 209430.75
A648: 65 | B648: Libya | C648: Middle East and North Africa | D648: 586630 | E648: 712751 | F648: 68047 | G648: 72 | H648: 68538 | I648: 27718 | J648: 35397 | K648: 2024 | L648: =AVERAGE(E648,F648,H648,) -> 212334
A649: 66 | B649: Jamaica | C649: Latin America and Caribbean | D649: 584170 | E649: 598077 | F649: 81892 | G649: 72 | H649: 74933 | I649: 22265 | J649: 4880 | K649: 2024 | L649: =AVERAGE(E649,F649,H649,) -> 188725.5
A650: 67 | B650: Peru | C650: Latin America and Caribbean | D650: 584090 | E650: 640313 | F650: 72994 | G650: 75 | H650: 71218 | I650: 19505 | J650: 4996 | K650: 2024 | L650: =AVERAGE(E650,F650,H650,) -> 196131.25
A651: 68 | B651: Dominican Republic | C651: Latin America and Caribbean | D651: 582280 | E651: 708565 | F651: 78657 | G651: 71 | H651: 84544 | I651: 21543 | J651: 34005 | K651: 2024 | L651: =AVERAGE(E651,F651,H651,) -> 217941.5
A652: 69 | B652: Mauritius | C652: Sub-Saharan Africa | D652: 581640 | E652: 733663 | F652: 83994 | G652: 70 | H652: 74224 | I652: 30632 | J652: 20477 | K652: 2024 | L652: =AVERAGE(E652,F652,H652,) -> 222970.25
A653: 70 | B653: Moldova | C653: Central and Eastern Europe | D653: 581590 | E653: 647210 | F653: 79008 | G653: 72 | H653: 80485 | I653: 19303 | J653: 7735 | K653: 2024 | L653: =AVERAGE(E653,F653,H653,) -> 201675.75
A654: 71 | B654: Russia | C654: Commonwealth of Independent States | D654: 578530 | E654: 767194 | F654: 83586 | G654: 71 | H654: 63875 | I654: 34384 | J654: 20957 | K654: 2024 | L654: =AVERAGE(E654,F654,H654,) -> 228663.75
A655: 72 | B655: Bolivia | C655: Latin America and Caribbean | D655: 578430 | E655: 568578 | F655: 72960 | G655: 70 | H655: 83335 | I655: 24842 | J655: 10575 | K655: 2024 | L655: =AVERAGE(E655,F655,H655,) -> 181218.25
A656: 73 | B656: Ecuador | C656: Latin America and Caribbean | D656: 572450 | E656: 614556 | F656: 71180 | G656: 74 | H656: 70203 | I656: 21807 | J656: 13620 | K656: 2024 | L656: =AVERAGE(E656,F656,H656,) -> 188984.75
A657: 74 | B657: Kyrgyzstan | C657: Commonwealth of Independent States | D657: 571350 | E657: 492532 | F657: 91364 | G657: 73 | H657: 96634 | I657: 56189 | J657: 5191 | K657: 2024 | L657: =AVERAGE(E657,F657,H657,) -> 170132.5
A658: 75 | B658: Montenegro | C658: Central and Eastern Europe | D658: 570700 | E658: 733711 | F658: 81532 | G658: 73 | H658: 73173 | I658: 27553 | J658: 22978 | K658: 2024 | L658: =AVERAGE(E658,F658,H658,) -> 222104
...

Sheet Calculations
B1: Happines Score | C1: GDP per capita | D1: Social support | E1: Healthy life expectancy | F1: Freedom to make life choices | G1: Generosity | H1: Perceptions of corruption
A2: Average | B2: =AVERAGE('Cleaned Data 2020 - 2024'!D:D) -> 552541.83 | C2: =AVERAGE('Cleaned Data 2020 - 2024'!E:E) -> 607029.65 | D2: =AVERAGE('Cleaned Data 2020 - 2024'!F:F) -> 70524.607 | E2: =AVERAGE('Cleaned Data 2020 - 2024'!G:G) -> 67.732687 | F2: =AVERAGE('Cleaned Data 2020 - 2024'!H:H) -> 69606.553 | G2: =AVERAGE('Cleaned Data 2020 - 2024'!I:I) -> 33827.086 | H2: =AVERAGE('Cleaned Data 2020 - 2024'!J:J) -> 56489.324
A3: Mean | B3: =MEDIAN('Cleaned Data 2020 - 2024'!D:D) -> 560350 | C3: =MEDIAN('Cleaned Data 2020 - 2024'!E:E) -> 637441 | D3: =MEDIAN('Cleaned Data 2020 - 2024'!F:F) -> 75753.5 | E3: =MEDIAN('Cleaned Data 2020 - 2024'!G:G) -> 68 | F3: =MEDIAN('Cleaned Data 2020 - 2024'!H:H) -> 72248 | G3: =MEDIAN('Cleaned Data 2020 - 2024'!I:I) -> 31429.5 | H3: =MEDIAN('Cleaned Data 2020 - 2024'!J:J) -> 67348.5
A5: Q1 | B5: =_xlfn.QUARTILE.INC('Cleaned Data 2020 - 2024'!D:D,1) -> 476165 | C5: =_xlfn.QUARTILE.INC('Cleaned Data 2020 - 2024'!E:E,1) -> 462299.5 | D5: =_xlfn.QUARTILE.INC('Cleaned Data 2020 - 2024'!F:F,1) -> 58147.5 | E5: =_xlfn.QUARTILE.INC('Cleaned Data 2020 - 2024'!G:G,1) -> 64 | F5: =_xlfn.QUARTILE.INC('Cleaned Data 2020 - 2024'!H:H,1) -> 58198.5 | G5: =_xlfn.QUARTILE.INC('Cleaned Data 2020 - 2024'!I:I,1) -> 20576.25 | H5: =_xlfn.QUARTILE.INC('Cleaned Data 2020 - 2024'!J:J,1) -> 23624.25
A6: Q3 | B6: =_xlfn.QUARTILE.INC('Cleaned Data 2020 - 2024'!D:D,3) -> 632842.5 | C6: =_xlfn.QUARTILE.INC('Cleaned Data 2020 - 2024'!E:E,3) -> 790752.5 | D6: =_xlfn.QUARTILE.INC('Cleaned Data 2020 - 2024'!F:F,3) -> 86581.75 | E6: =_xlfn.QUARTILE.INC('Cleaned Data 2020 - 2024'!G:G,3) -> 73 | F6: =_xlfn.QUARTILE.INC('Cleaned Data 2020 - 2024'!H:H,3) -> 84669 | G6: =_xlfn.QUARTILE.INC('Cleaned Data 2020 - 2024'!I:I,3) -> 44819.75 | H6: =_xlfn.QUARTILE.INC('Cleaned Data 2020 - 2024'!J:J,3) -> 85440.25
A7: IQR | B7: =B6-B5 -> 156677.5 | C7: =C6-C5 -> 328453 | D7: =D6-D5 -> 28434.25 | E7: =E6-E5 -> 9 | F7: =F6-F5 -> 26470.5 | G7: =G6-G5 -> 24243.5 | H7: =H6-H5 -> 61816
A9: Lower Bound | B9: =B5-(1.5*B7) -> 241148.75 | C9: =C5-(1.5*C7) -> -30380 | D9: =D5-(1.5*D7) -> 15496.125 | E9: =E5-(1.5*E7) -> 50.5 | F9: =F5-(1.5*F7) -> 18492.75 | G9: =G5-(1.5*G7) -> -15789 | H9: =H5-(1.5*H7) -> -69099.75
A10: Upper Bound | B10: =B6+(1.5*B7) -> 867858.75 | C10: =C6+(1.5*C7) -> 1283432 | D10: =D6+(1.5*D7) -> 129233.12 | E10: =E6+(1.5*E7) -> 86.5 | F10: =F6+(1.5*F7) -> 124374.75 | G10: =G6+(1.5*G7) -> 81185 | H10: =H6+(1.5*H7) -> 178164.25
A12: Which country with a below average perception of corruption has the highest gdp per capita?
A13: Country | B13: Average GDP | C13: AVG Corruption | D13: Below Average | E13: Highest GDP | F13: Country
A14: Finland | B14: =AVERAGEIF('Cleaned Data 2020 - 2024'!B:B,Calculations!A14,'Cleaned Data 2020 - 2024'!E:E) -> 847724.2 | C14: =AVERAGEIF('Cleaned Data 2020 - 2024'!B:B,Calculations!A14,'Cleaned Data 2020 - 2024'!J:J) -> 42589.2 | D14: =IF(C14<$H$2,"Y","N") -> Y | E14: =_xlfn.MAXIFS(B14:B169,D14:D169,"Y") -> 1000000 | F14: =_xlfn.XLOOKUP(E14,B14:B169,A14:A169) -> Luxembourg
A15: Denmark | B15: =AVERAGEIF('Cleaned Data 2020 - 2024'!B:B,Calculations!A15,'Cleaned Data 2020 - 2024'!E:E) -> 876487.4 | C15: =AVERAGEIF('Cleaned Data 2020 - 2024'!B:B,Calculations!A15,'Cleaned Data 2020 - 2024'!J:J) -> 42156.8 | D15: =IF(C15<$H$2,"Y","N") -> Y
A16: Switzerland | B16: =AVERAGEIF('Cleaned Data 2020 - 2024'!B:B,Calculations!A16,'Cleaned Data 2020 - 2024'!E:E) -> 911207.2 | C16: =AVERAGEIF('Cleaned Data 2020 - 2024'!B:B,Calculations!A16,'Cleaned Data 2020 - 2024'!J:J) -> 45677.8 | D16: =IF(C16<$H$2,"Y","N") -> Y
A17: Iceland | B17: =AVERAGEIF('Cleaned Data 2020 - 2024'!B:B,Calculations!A17,'Cleaned Data 2020 - 2024'!E:E) -> 867987.8 | C17: =AVERAGEIF('Cleaned Data 2020 - 2024'!B:B,Calculations!A17,'Cleaned Data 2020 - 2024'!J:J) -> 54551.2 | D17: =IF(C17<$H$2,"Y","N") -> Y
A18: Norway | B18: =AVERAGEIF('Cleaned Data 2020 - 2024'!B:B,Calculations!A18,'Cleaned Data 2020 - 2024'!E:E) -> 906190.6 | C18: =AVERAGEIF('Cleaned Data 2020 - 2024'!B:B,Calculations!A18,'Cleaned Data 2020 - 2024'!J:J) -> 44576.8 | D18: =IF(C18<$H$2,"Y","N") -> Y
A19: Netherlands | B19: =AVERAGEIF('Cleaned Data 2020 - 2024'!B:B,Calculations!A19,'Cleaned Data 2020 - 2024'!E:E) -> 875952.8 | C19: =AVERAGEIF('Cleaned Data 2020 - 2024'!B:B,Calculations!A19,'Cleaned Data 2020 - 2024'!J:J) -> 45326.8 | D19: =IF(C19<$H$2,"Y","N") -> Y
A20: Sweden | B20: =AVERAGEIF('Cleaned Data 2020 - 2024'!B:B,Calculations!A20,'Cleaned Data 2020 - 2024'!E:E) -> 864947.4 | C20: =AVERAGEIF('Cleaned Data 2020 - 2024'!B:B,Calculations!A20,'Cleaned Data 2020 - 2024'!J:J) -> 44157 | D20: =IF(C20<$H$2,"Y","N") -> Y
A21: New Zealand | B21: =AVERAGEIF('Cleaned Data 2020 - 2024'!B:B,Calculations!A21,'Cleaned Data 2020 - 2024'!E:E) -> 825880 | C21: =AVERAGEIF('Cleaned Data 2020 - 2024'!B:B,Calculations!A21,'Cleaned Data 2020 - 2024'!J:J) -> 42778.4 | D21: =IF(C21<$H$2,"Y","N") -> Y
A22: Austria | B22: =AVERAGEIF('Cleaned Data 2020 - 2024'!B:B,Calculations!A22,'Cleaned Data 2020 - 2024'!E:E) -> 868064 | C22: =AVERAGEIF('Cleaned Data 2020 - 2024'!B:B,Calculations!A22,'Cleaned Data 2020 - 2024'!J:J) -> 49532.4 | D22: =IF(C22<$H$2,"Y","N") -> Y
A23: Luxembourg | B23: =AVERAGEIF('Cleaned Data 2020 - 2024'!B:B,Calculations!A23,'Cleaned Data 2020 - 2024'!E:E) -> 1000000 | C23: =AVERAGEIF('Cleaned Data 2020 - 2024'!B:B,Calculations!A23,'Cleaned Data 2020 - 2024'!J:J) -> 46678.8 | D23: =IF(C23<$H$2,"Y","N") -> Y
A24: Canada | B24: =AVERAGEIF('Cleaned Data 2020 - 2024'!B:B,Calculations!A24,'Cleaned Data 2020 - 2024'!E:E) -> 848398.6 | C24: =AVERAGEIF('Cleaned Data 2020 - 2024'!B:B,Calculations!A24,'Cleaned Data 2020 - 2024'!J:J) -> 46924 | D24: =IF(C24<$H$2,"Y","N") -> Y
A25: Australia | B25: =AVERAGEIF('Cleaned Data 2020 - 2024'!B:B,Calculations!A25,'Cleaned Data 2020 - 2024'!E:E) -> 854467.2 | C25: =AVERAGEIF('Cleaned Data 2020 - 2024'!B:B,Calculations!A25,'Cleaned Data 2020 - 2024'!J:J) -> 47604.8 | D25: =IF(C25<$H$2,"Y","N") -> Y
A26: United Kingdom | B26: =AVERAGEIF('Cleaned Data 2020 - 2024'!B:B,Calculations!A26,'Cleaned Data 2020 - 2024'!E:E) -> 836313.8 | C26: =AVERAGEIF('Cleaned Data 2020 - 2024'!B:B,Calculations!A26,'Cleaned Data 2020 - 2024'!J:J) -> 48008.4 | D26: =IF(C26<$H$2,"Y","N") -> Y
... A169: Turkiye | B169: =AVERAGEIF('Cleaned Data 2020 - 2024'!B:B,Calculations!A169,'Cleaned Data 2020 - 2024'!E:E) -> 787156.5 | C169: =AVERAGEIF('Cleaned Data 2020 - 2024'!B:B,Calculations!A169,'Cleaned Data 2020 - 2024'!J:J) -> 51408 | D169: =IF(C169<$H$2,"Y","N") -> Y
A171: What are the top ten countries with improved happinness scores from 2020 - 2024?
B172: Happiness Score
A173: Country | B173: 2020 | C173: 2021 | D173: 2022 | E173: 2023 | F173: 2024 | G173: Change in Happiness | H173: Rank
A174: Finland | B174: {=_xlfn.XLOOKUP(1,('Cleaned Data 2020 - 2024'!$B:$B=Calculations!A174)*('Cleaned Data 2020 - 2024'!$K:$K=Calculations!B173),'Cleaned Data 2020 - 2024'!$D:$D)} -> 780870 | C174: {=_xlfn.XLOOKUP(1,('Cleaned Data 2020 - 2024'!$B:$B=$A$174)*('Cleaned Data 2020 - 2024'!$K:$K=Calculations!C173),'Cleaned Data 2020 - 2024'!$D:$D)} -> 784210 | D174: {=_xlfn.XLOOKUP(1,('Cleaned Data 2020 - 2024'!$B:$B=$A$174)*('Cleaned Data 2020 - 2024'!$K:$K=Calculations!D173),'Cleaned Data 2020 - 2024'!$D:$D)} -> 782100 | E174: {=_xlfn.XLOOKUP(1,('Cleaned Data 2020 - 2024'!$B:$B=$A$174)*('Cleaned Data 2020 - 2024'!$K:$K=Calculations!E173),'Cleaned Data 2020 - 2024'!$D:$D)} -> 780420 | F174: {=_xlfn.XLOOKUP(1,('Cleaned Data 2020 - 2024'!$B:$B=$A$174)*('Cleaned Data 2020 - 2024'!$K:$K=Calculations!F173),'Cleaned Data 2020 - 2024'!$D:$D)} -> 774070 | G174: =F174-B174 -> -6800 | H174: =_xlfn.RANK.EQ(G174,$G$174:$G$329,0) -> 103
A175: Denmark | B175: {=_xlfn.XLOOKUP(1,('Cleaned Data 2020 - 2024'!$B:$B=Calculations!A175)*('Cleaned Data 2020 - 2024'!$K:$K=$B$173),'Cleaned Data 2020 - 2024'!$D:$D)} -> 764560 | C175: {=_xlfn.XLOOKUP(1,('Cleaned Data 2020 - 2024'!B:B=A175)*('Cleaned Data 2020 - 2024'!K:K=$C$173),'Cleaned Data 2020 - 2024'!D:D)} -> 761950 | D175: {=_xlfn.XLOOKUP(1,('Cleaned Data 2020 - 2024'!$B:$B=$A175)*('Cleaned Data 2020 - 2024'!$K:$K=$D$173),'Cleaned Data 2020 - 2024'!$D:$D)} -> 763620 | E175: {=_xlfn.XLOOKUP(1,('Cleaned Data 2020 - 2024'!$B:$B=A175)*('Cleaned Data 2020 - 2024'!$K:$K=E173),'Cleaned Data 2020 - 2024'!$D:$D)} -> 758640 | F175: {=_xlfn.XLOOKUP(1,('Cleaned Data 2020 - 2024'!$B:$B=A175)*('Cleaned Data 2020 - 2024'!$K:$K=$F$173),'Cleaned Data 2020 - 2024'!$D:$D)} -> 758270 | G175: =F175-B175 -> -6290 | H175: =_xlfn.RANK.EQ(G175,$G$174:$G$329,0) -> 100
A176: Switzerland | B176: {=_xlfn.XLOOKUP(1,('Cleaned Data 2020 - 2024'!$B:$B=Calculations!A176)*('Cleaned Data 2020 - 2024'!$K:$K=$B$173),'Cleaned Data 2020 - 2024'!$D:$D)} -> 755990 | C176: {=_xlfn.XLOOKUP(1,('Cleaned Data 2020 - 2024'!B:B=A176)*('Cleaned Data 2020 - 2024'!K:K=$C$173),'Cleaned Data 2020 - 2024'!D:D)} -> 757150 | D176: {=_xlfn.XLOOKUP(1,('Cleaned Data 2020 - 2024'!$B:$B=$A176)*('Cleaned Data 2020 - 2024'!$K:$K=$D$173),'Cleaned Data 2020 - 2024'!$D:$D)} -> 751160 | E176: {=_xlfn.XLOOKUP(1,('Cleaned Data 2020 - 2024'!$B:$B=A176)*('Cleaned Data 2020 - 2024'!$K:$K=$E$173),'Cleaned Data 2020 - 2024'!$D:$D)} -> 724010 | F176: {=_xlfn.XLOOKUP(1,('Cleaned Data 2020 - 2024'!$B:$B=A176)*('Cleaned Data 2020 - 2024'!$K:$K=$F$173),'Cleaned Data 2020 - 2024'!$D:$D)} -> 706020 | G176: =F176-B176 -> -49970 | H176: =_xlfn.RANK.EQ(G176,$G$174:$G$329,0) -> 145
A177: Iceland | B177: {=_xlfn.XLOOKUP(1,('Cleaned Data 2020 - 2024'!$B:$B=Calculations!A177)*('Cleaned Data 2020 - 2024'!$K:$K=$B$173),'Cleaned Data 2020 - 2024'!$D:$D)} -> 750450 | C177: {=_xlfn.XLOOKUP(1,('Cleaned Data 2020 - 2024'!B:B=A177)*('Cleaned Data 2020 - 2024'!K:K=$C$173),'Cleaned Data 2020 - 2024'!D:D)} -> 755390 | D177: {=_xlfn.XLOOKUP(1,('Cleaned Data 2020 - 2024'!$B:$B=$A177)*('Cleaned Data 2020 - 2024'!$K:$K=$D$173),'Cleaned Data 2020 - 2024'!$D:$D)} -> 755750 | E177: {=_xlfn.XLOOKUP(1,('Cleaned Data 2020 - 2024'!$B:$B=A177)*('Cleaned Data 2020 - 2024'!$K:$K=$E$173),'Cleaned Data 2020 - 2024'!$D:$D)} -> 752960 | F177: {=_xlfn.XLOOKUP(1,('Cleaned Data 2020 - 2024'!$B:$B=A177)*('Cleaned Data 2020 - 2024'!$K:$K=$F$173),'Cleaned Data 2020 - 2024'!$D:$D)} -> 752510 | G177: =F177-B177 -> 2060 | H177: =_xlfn.RANK.EQ(G177,$G$174:$G$329,0) -> 78
A178: Norway | B178: {=_xlfn.XLOOKUP(1,('Cleaned Data 2020 - 2024'!$B:$B=Calculations!A178)*('Cleaned Data 2020 - 2024'!$K:$K=$B$173),'Cleaned Data 2020 - 2024'!$D:$D)} -> 748800 | C178: {=_xlfn.XLOOKUP(1,('Cleaned Data 2020 - 2024'!B:B=A178)*('Cleaned Data 2020 - 2024'!K:K=$C$173),'Cleaned Data 2020 - 2024'!D:D)} -> 739250 | D178: {=_xlfn.XLOOKUP(1,('Cleaned Data 2020 - 2024'!$B:$B=$A178)*('Cleaned Data 2020 - 2024'!$K:$K=$D$173),'Cleaned Data 2020 - 2024'!$D:$D)} -> 736510 | E178: {=_xlfn.XLOOKUP(1,('Cleaned Data 2020 - 2024'!$B:$B=A178)*('Cleaned Data 2020 - 2024'!$K:$K=$E$173),'Cleaned Data 2020 - 2024'!$D:$D)} -> 731550 | F178: {=_xlfn.XLOOKUP(1,('Cleaned Data 2020 - 2024'!$B:$B=A178)*('Cleaned Data 2020 - 2024'!$K:$K=$F$173),'Cleaned Data 2020 - 2024'!$D:$D)} -> 730170 | G178: =F178-B178 -> -18630 | H178: =_xlfn.RANK.EQ(G178,$G$174:$G$329,0) -> 118
A179: Netherlands | B179: {=_xlfn.XLOOKUP(1,('Cleaned Data 2020 - 2024'!$B:$B=Calculations!A179)*('Cleaned Data 2020 - 2024'!$K:$K=$B$173),'Cleaned Data 2020 - 2024'!$D:$D)} -> 744890 | C179: {=_xlfn.XLOOKUP(1,('Cleaned Data 2020 - 2024'!B:B=A179)*('Cleaned Data 2020 - 2024'!K:K=$C$173),'Cleaned Data 2020 - 2024'!D:D)} -> 746400 | D179: {=_xlfn.XLOOKUP(1,('Cleaned Data 2020 - 2024'!$B:$B=$A179)*('Cleaned Data 2020 - 2024'!$K:$K=$D$173),'Cleaned Data 2020 - 2024'!$D:$D)} -> 741490 | E179: {=_xlfn.XLOOKUP(1,('Cleaned Data 2020 - 2024'!$B:$B=A179)*('Cleaned Data 2020 - 2024'!$K:$K=$E$173),'Cleaned Data 2020 - 2024'!$D:$D)} -> 740300 | F179: {=_xlfn.XLOOKUP(1,('Cleaned Data 2020 - 2024'!$B:$B=A179)*('Cleaned Data 2020 - 2024'!$K:$K=$F$173),'Cleaned Data 2020 - 2024'!$D:$D)} -> 731940 | G179: =F179-B179 -> -12950 | H179: =_xlfn.RANK.EQ(G179,$G$174:$G$329,0) -> 113
A180: Sweden | B180: {=_xlfn.XLOOKUP(1,('Cleaned Data 2020 - 2024'!$B:$B=Calculations!A180)*('Cleaned Data 2020 - 2024'!$K:$K=$B$173),'Cleaned Data 2020 - 2024'!$D:$D)} -> 735350 | C180: {=_xlfn.XLOOKUP(1,('Cleaned Data 2020 - 2024'!B:B=A180)*('Cleaned Data 2020 - 2024'!K:K=$C$173),'Cleaned Data 2020 - 2024'!D:D)} -> 736270 | D180: {=_xlfn.XLOOKUP(1,('Cleaned Data 2020 - 2024'!$B:$B=$A180)*('Cleaned Data 2020 - 2024'!$K:$K=$D$173),'Cleaned Data 2020 - 2024'!$D:$D)} -> 738430 | E180: {=_xlfn.XLOOKUP(1,('Cleaned Data 2020 - 2024'!$B:$B=A180)*('Cleaned Data 2020 - 2024'!$K:$K=$E$173),'Cleaned Data 2020 - 2024'!$D:$D)} -> 739520 | F180: {=_xlfn.XLOOKUP(1,('Cleaned Data 2020 - 2024'!$B:$B=A180)*('Cleaned Data 2020 - 2024'!$K:$K=$F$173),'Cleaned Data 2020 - 2024'!$D:$D)} -> 734410 | G180: =F180-B180 -> -940 | H180: =_xlfn.RANK.EQ(G180,$G$174:$G$329,0) -> 90
A181: New Zealand | B181: {=_xlfn.XLOOKUP(1,('Cleaned Data 2020 - 2024'!$B:$B=Calculations!A181)*('Cleaned Data 2020 - 2024'!$K:$K=$B$173),'Cleaned Data 2020 - 2024'!$D:$D)} -> 729960 | C181: {=_xlfn.XLOOKUP(1,('Cleaned Data 2020 - 2024'!B:B=A181)*('Cleaned Data 2020 - 2024'!K:K=$C$173),'Cleaned Data 2020 - 2024'!D:D)} -> 727660 | D181: {=_xlfn.XLOOKUP(1,('Cleaned Data 2020 - 2024'!$B:$B=$A181)*('Cleaned Data 2020 - 2024'!$K:$K=$D$173),'Cleaned Data 2020 - 2024'!$D:$D)} -> 719980 | E181: {=_xlfn.XLOOKUP(1,('Cleaned Data 2020 - 2024'!$B:$B=A181)*('Cleaned Data 2020 - 2024'!$K:$K=$E$173),'Cleaned Data 2020 - 2024'!$D:$D)} -> 712290 | F181: {=_xlfn.XLOOKUP(1,('Cleaned Data 2020 - 2024'!$B:$B=A181)*('Cleaned Data 2020 - 2024'!$K:$K=$F$173),'Cleaned Data 2020 - 2024'!$D:$D)} -> 702920 | G181: =F181-B181 -> -27040 | H181: =_xlfn.RANK.EQ(G181,$G$174:$G$329,0) -> 128
A182: Austria | B182: {=_xlfn.XLOOKUP(1,('Cleaned Data 2020 - 2024'!$B:$B=Calculations!A182)*('Cleaned Data 2020 - 2024'!$K:$K=$B$173),'Cleaned Data 2020 - 2024'!$D:$D)} -> 729420 | C182: {=_xlfn.XLOOKUP(1,('Cleaned Data 2020 - 2024'!B:B=A182)*('Cleaned Data 2020 - 2024'!K:K=$C$173),'Cleaned Data 2020 - 2024'!D:D)} -> 726780 | D182: {=_xlfn.XLOOKUP(1,('Cleaned Data 2020 - 2024'!$B:$B=$A182)*('Cleaned Data 2020 - 2024'!$K:$K=$D$173),'Cleaned Data 2020 - 2024'!$D:$D)} -> 716300 | E182: {=_xlfn.XLOOKUP(1,('Cleaned Data 2020 - 2024'!$B:$B=A182)*('Cleaned Data 2020 - 2024'!$K:$K=$E$173),'Cleaned Data 2020 - 2024'!$D:$D)} -> 709730 | F182: {=_xlfn.XLOOKUP(1,('Cleaned Data 2020 - 2024'!$B:$B=A182)*('Cleaned Data 2020 - 2024'!$K:$K=$F$173),'Cleaned Data 2020 - 2024'!$D:$D)} -> 690470 | G182: =F182-B182 -> -38950 | H182: =_xlfn.RANK.EQ(G182,$G$174:$G$329,0) -> 137
A183: Luxembourg | B183: {=_xlfn.XLOOKUP(1,('Cleaned Data 2020 - 2024'!$B:$B=Calculations!A183)*('Cleaned Data 2020 - 2024'!$K:$K=$B$173),'Cleaned Data 2020 - 2024'!$D:$D)} -> 723750 | C183: {=_xlfn.XLOOKUP(1,('Cleaned Data 2020 - 2024'!B:B=A183)*('Cleaned Data 2020 - 2024'!K:K=$C$173),'Cleaned Data 2020 - 2024'!D:D)} -> 732440 | D183: {=_xlfn.XLOOKUP(1,('Cleaned Data 2020 - 2024'!$B:$B=$A183)*('Cleaned Data 2020 - 2024'!$K:$K=$D$173),'Cleaned Data 2020 - 2024'!$D:$D)} -> 740400 | E183: {=_xlfn.XLOOKUP(1,('Cleaned Data 2020 - 2024'!$B:$B=A183)*('Cleaned Data 2020 - 2024'!$K:$K=$E$173),'Cleaned Data 2020 - 2024'!$D:$D)} -> 722790 | F183: {=_xlfn.XLOOKUP(1,('Cleaned Data 2020 - 2024'!$B:$B=A183)*('Cleaned Data 2020 - 2024'!$K:$K=$F$173),'Cleaned Data 2020 - 2024'!$D:$D)} -> 712190 | G183: =F183-B183 -> -11560 | H183: =_xlfn.RANK.EQ(G183,$G$174:$G$329,0) -> 110
A184: Canada | B184: {=_xlfn.XLOOKUP(1,('Cleaned Data 2020 - 2024'!$B:$B=Calculations!A184)*('Cleaned Data 2020 - 2024'!$K:$K=$B$173),'Cleaned Data 2020 - 2024'!$D:$D)} -> 723210 | C184: {=_xlfn.XLOOKUP(1,('Cleaned Data 2020 - 2024'!B:B=A184)*('Cleaned Data 2020 - 2024'!K:K=$C$173),'Cleaned Data 2020 - 2024'!D:D)} -> 710330 | D184: {=_xlfn.XLOOKUP(1,('Cleaned Data 2020 - 2024'!$B:$B=$A184)*('Cleaned Data 2020 - 2024'!$K:$K=$D$173),'Cleaned Data 2020 - 2024'!$D:$D)} -> 702510 | E184: {=_xlfn.XLOOKUP(1,('Cleaned Data 2020 - 2024'!$B:$B=A184)*('Cleaned Data 2020 - 2024'!$K:$K=$E$173),'Cleaned Data 2020 - 2024'!$D:$D)} -> 696070 | F184: {=_xlfn.XLOOKUP(1,('Cleaned Data 2020 - 2024'!$B:$B=A184)*('Cleaned Data 2020 - 2024'!$K:$K=$F$173),'Cleaned Data 2020 - 2024'!$D:$D)} -> 689960 | G184: =F184-B184 -> -33250 | H184: =_xlfn.RANK.EQ(G184,$G$174:$G$329,0) -> 134
A185: Australia | B185: {=_xlfn.XLOOKUP(1,('Cleaned Data 2020 - 2024'!$B:$B=Calculations!A185)*('Cleaned Data 2020 - 2024'!$K:$K=$B$173),'Cleaned Data 2020 - 2024'!$D:$D)} -> 722280 | C185: {=_xlfn.XLOOKUP(1,('Cleaned Data 2020 - 2024'!B:B=A185)*('Cleaned Data 2020 - 2024'!K:K=$C$173),'Cleaned Data 2020 - 2024'!D:D)} -> 718350 | D185: {=_xlfn.XLOOKUP(1,('Cleaned Data 2020 - 2024'!$B:$B=$A185)*('Cleaned Data 2020 - 2024'!$K:$K=$D$173),'Cleaned Data 2020 - 2024'!$D:$D)} -> 716210 | E185: {=_xlfn.XLOOKUP(1,('Cleaned Data 2020 - 2024'!$B:$B=A185)*('Cleaned Data 2020 - 2024'!$K:$K=$E$173),'Cleaned Data 2020 - 2024'!$D:$D)} -> 709460 | F185: {=_xlfn.XLOOKUP(1,('Cleaned Data 2020 - 2024'!$B:$B=A185)*('Cleaned Data 2020 - 2024'!$K:$K=$F$173),'Cleaned Data 2020 - 2024'!$D:$D)} -> 705690 | G185: =F185-B185 -> -16590 | H185: =_xlfn.RANK.EQ(G185,$G$174:$G$329,0) -> 115
A186: United Kingdom | B186: {=_xlfn.XLOOKUP(1,('Cleaned Data 2020 - 2024'!$B:$B=Calculations!A186)*('Cleaned Data 2020 - 2024'!$K:$K=$B$173),'Cleaned Data 2020 - 2024'!$D:$D)} -> 716450 | C186: {=_xlfn.XLOOKUP(1,('Cleaned Data 2020 - 2024'!B:B=A186)*('Cleaned Data 2020 - 2024'!K:K=$C$173),'Cleaned Data 2020 - 2024'!D:D)} -> 706360 | D186: {=_xlfn.XLOOKUP(1,('Cleaned Data 2020 - 2024'!$B:$B=$A186)*('Cleaned Data 2020 - 2024'!$K:$K=$D$173),'Cleaned Data 2020 - 2024'!$D:$D)} -> 694250 | E186: {=_xlfn.XLOOKUP(1,('Cleaned Data 2020 - 2024'!$B:$B=A186)*('Cleaned Data 2020 - 2024'!$K:$K=$E$173),'Cleaned Data 2020 - 2024'!$D:$D)} -> 679560 | F186: {=_xlfn.XLOOKUP(1,('Cleaned Data 2020 - 2024'!$B:$B=A186)*('Cleaned Data 2020 - 2024'!$K:$K=$F$173),'Cleaned Data 2020 - 2024'!$D:$D)} -> 674900 | G186: =F186-B186 -> -41550 | H186: =_xlfn.RANK.EQ(G186,$G$174:$G$329,0) -> 138
...

Sheet Calculations 2
A1: Regional indicator | B1: Avergage GDP | C1: Rank | E1: Regional indicator | F1: Business Indicator | G1: Ranking | R1: Which region has the strongest business indicator from 2020-2024?
A2: Western Europe | B2: =AVERAGEIF('Cleaned Data 2020 - 2024'!C:C,'Calculations 2'!A2,'Cleaned Data 2020 - 2024'!E:E) -> 854795.09 | C2: =_xlfn.RANK.EQ(B2,$B$2:$B$11,0) -> 2 | E2: Western Europe | F2: =AVERAGEIF('Cleaned Data 2020 - 2024'!C:C,'Calculations 2'!E2,'Cleaned Data 2020 - 2024'!L:L) -> 256937.85 | G2: =_xlfn.RANK.EQ(F2,$F$2:$F$11,0) -> 2
A3: North America and ANZ | B3: =AVERAGEIF('Cleaned Data 2020 - 2024'!C:C,'Calculations 2'!A3,'Cleaned Data 2020 - 2024'!E:E) -> 855837.1 | C3: =_xlfn.RANK.EQ(B3,$B$2:$B$11,0) -> 1 | E3: North America and ANZ | F3: =AVERAGEIF('Cleaned Data 2020 - 2024'!C:C,'Calculations 2'!E3,'Cleaned Data 2020 - 2024'!L:L) -> 258267.48 | G3: =_xlfn.RANK.EQ(F3,$F$2:$F$11,0) -> 1
A4: Middle East and North Africa | B4: =AVERAGEIF('Cleaned Data 2020 - 2024'!C:C,'Calculations 2'!A4,'Cleaned Data 2020 - 2024'!E:E) -> 651471.44 | C4: =_xlfn.RANK.EQ(B4,$B$2:$B$11,0) -> 5 | E4: Middle East and North Africa | F4: =AVERAGEIF('Cleaned Data 2020 - 2024'!C:C,'Calculations 2'!E4,'Cleaned Data 2020 - 2024'!L:L) -> 193074.89 | G4: =_xlfn.RANK.EQ(F4,$F$2:$F$11,0) -> 6
A5: Latin America and Caribbean | B5: =AVERAGEIF('Cleaned Data 2020 - 2024'!C:C,'Calculations 2'!A5,'Cleaned Data 2020 - 2024'!E:E) -> 590427.86 | C5: =_xlfn.RANK.EQ(B5,$B$2:$B$11,0) -> 8 | E5: Latin America and Caribbean | F5: =AVERAGEIF('Cleaned Data 2020 - 2024'!C:C,'Calculations 2'!E5,'Cleaned Data 2020 - 2024'!L:L) -> 186341.13 | G5: =_xlfn.RANK.EQ(F5,$F$2:$F$11,0) -> 8
A6: Central and Eastern Europe | B6: =AVERAGEIF('Cleaned Data 2020 - 2024'!C:C,'Calculations 2'!A6,'Cleaned Data 2020 - 2024'!E:E) -> 710406.95 | C6: =_xlfn.RANK.EQ(B6,$B$2:$B$11,0) -> 4 | E6: Central and Eastern Europe | F6: =AVERAGEIF('Cleaned Data 2020 - 2024'!C:C,'Calculations 2'!E6,'Cleaned Data 2020 - 2024'!L:L) -> 216027.77 | G6: =_xlfn.RANK.EQ(F6,$F$2:$F$11,0) -> 4
A7: East Asia | B7: =AVERAGEIF('Cleaned Data 2020 - 2024'!C:C,'Calculations 2'!A7,'Cleaned Data 2020 - 2024'!E:E) -> 738020.83 | C7: =_xlfn.RANK.EQ(B7,$B$2:$B$11,0) -> 3 | E7: East Asia | F7: =AVERAGEIF('Cleaned Data 2020 - 2024'!C:C,'Calculations 2'!E7,'Cleaned Data 2020 - 2024'!L:L) -> 220996.03 | G7: =_xlfn.RANK.EQ(F7,$F$2:$F$11,0) -> 3
A8: Southeast Asia | B8: =AVERAGEIF('Cleaned Data 2020 - 2024'!C:C,'Calculations 2'!A8,'Cleaned Data 2020 - 2024'!E:E) -> 619993.46 | C8: =_xlfn.RANK.EQ(B8,$B$2:$B$11,0) -> 6 | E8: Southeast Asia | F8: =AVERAGEIF('Cleaned Data 2020 - 2024'!C:C,'Calculations 2'!E8,'Cleaned Data 2020 - 2024'!L:L) -> 195404.59 | G8: =_xlfn.RANK.EQ(F8,$F$2:$F$11,0) -> 5
A9: Commonwealth of Independent States | B9: =AVERAGEIF('Cleaned Data 2020 - 2024'!C:C,'Calculations 2'!A9,'Cleaned Data 2020 - 2024'!E:E) -> 599065.67 | C9: =_xlfn.RANK.EQ(B9,$B$2:$B$11,0) -> 7 | E9: Commonwealth of Independent States | F9: =AVERAGEIF('Cleaned Data 2020 - 2024'!C:C,'Calculations 2'!E9,'Cleaned Data 2020 - 2024'!L:L) -> 188349.22 | G9: =_xlfn.RANK.EQ(F9,$F$2:$F$11,0) -> 7
A10: Sub-Saharan Africa | B10: =AVERAGEIF('Cleaned Data 2020 - 2024'!C:C,'Calculations 2'!A10,'Cleaned Data 2020 - 2024'!E:E) -> 367256.23 | C10: =_xlfn.RANK.EQ(B10,$B$2:$B$11,0) -> 10 | E10: Sub-Saharan Africa | F10: =AVERAGEIF('Cleaned Data 2020 - 2024'!C:C,'Calculations 2'!E10,'Cleaned Data 2020 - 2024'!L:L) -> 118579.08 | G10: =_xlfn.RANK.EQ(F10,$F$2:$F$11,0) -> 10
A11: South Asia | B11: =AVERAGEIF('Cleaned Data 2020 - 2024'!C:C,'Calculations 2'!A11,'Cleaned Data 2020 - 2024'!E:E) -> 443632.87 | C11: =_xlfn.RANK.EQ(B11,$B$2:$B$11,0) -> 9 | E11: South Asia | F11: =AVERAGEIF('Cleaned Data 2020 - 2024'!C:C,'Calculations 2'!E11,'Cleaned Data 2020 - 2024'!L:L) -> 137294.32 | G11: =_xlfn.RANK.EQ(F11,$F$2:$F$11,0) -> 9
A15: Regional indicator | B15: Average Happiness
A16: Western Europe | B16: =AVERAGEIF('Cleaned Data 2020 - 2024'!C:C,'Calculations 2'!A16,'Cleaned Data 2020 - 2024'!D:D) -> 690886.42
A17: North America and ANZ | B17: =AVERAGEIF('Cleaned Data 2020 - 2024'!C:C,'Calculations 2'!A17,'Cleaned Data 2020 - 2024'!D:D) -> 706776
A18: Middle East and North Africa | B18: =AVERAGEIF('Cleaned Data 2020 - 2024'!C:C,'Calculations 2'!A18,'Cleaned Data 2020 - 2024'!D:D) -> 517234.56
A19: Latin America and Caribbean | B19: =AVERAGEIF('Cleaned Data 2020 - 2024'!C:C,'Calculations 2'!A19,'Cleaned Data 2020 - 2024'!D:D) -> 598887.86
A20: Central and Eastern Europe | B20: =AVERAGEIF('Cleaned Data 2020 - 2024'!C:C,'Calculations 2'!A20,'Cleaned Data 2020 - 2024'!D:D) -> 597108.78
A21: East Asia | B21: =AVERAGEIF('Cleaned Data 2020 - 2024'!C:C,'Calculations 2'!A21,'Cleaned Data 2020 - 2024'!D:D) -> 572512.5 | E21: Year | F21: 2024
A22: Southeast Asia | B22: =AVERAGEIF('Cleaned Data 2020 - 2024'!C:C,'Calculations 2'!A22,'Cleaned Data 2020 - 2024'!D:D) -> 548149.27
A23: Commonwealth of Independent States | B23: =AVERAGEIF('Cleaned Data 2020 - 2024'!C:C,'Calculations 2'!A23,'Cleaned Data 2020 - 2024'!D:D) -> 547345.51 | E23: Row Labels | F23: Highest Happiness | G23: Lowest Happiness | H23: Variance | I23: Which Region had the largest variance in Happiness Scores between countries in 2024?
A24: Sub-Saharan Africa | B24: =AVERAGEIF('Cleaned Data 2020 - 2024'!C:C,'Calculations 2'!A24,'Cleaned Data 2020 - 2024'!D:D) -> 443474.17 | E24: Central and Eastern Europe | F24: 674330 | G24: 530420 | H24: =GETPIVOTDATA("Highest Happiness",$E$23,"Regional indicator","Central and Eastern Europe")-GETPIVOTDATA("Lowest Happiness",$E$23,"Regional indicator","Central and Eastern Europe") -> 143910
A25: South Asia | B25: =AVERAGEIF('Cleaned Data 2020 - 2024'!C:C,'Calculations 2'!A25,'Cleaned Data 2020 - 2024'!D:D) -> 418413.67 | E25: Commonwealth of Independent States | F25: 619500 | G25: 487300 | H25: =GETPIVOTDATA("Highest Happiness",$E$23,"Regional indicator","Commonwealth of Independent States")-GETPIVOTDATA("Lowest Happiness",$E$23,"Regional indicator","Commonwealth of Independent States") -> 132200
E26: East Asia | F26: 650350 | G26: 513890 | H26: =GETPIVOTDATA("Highest Happiness",$E$23,"Regional indicator","East Asia")-GETPIVOTDATA("Lowest Happiness",$E$23,"Regional indicator","East Asia") -> 136460
E27: Latin America and Caribbean | F27: 695540 | G27: 560670 | H27: =GETPIVOTDATA("Highest Happiness",$E$23,"Regional indicator","Latin America and Caribbean")-GETPIVOTDATA("Lowest Happiness",$E$23,"Regional indicator","Latin America and Caribbean") -> 134870
A28: Regional indicator | B28: Average perception of corruption | E28: Middle East and North Africa | F28: 734110 | G28: 270650 | H28: =GETPIVOTDATA("Highest Happiness",$E$23,"Regional indicator","Middle East and North Africa")-GETPIVOTDATA("Lowest Happiness",$E$23,"Regional indicator","Middle East and North Africa") -> 463460
A29: Western Europe | B29: =AVERAGEIF('Cleaned Data 2020 - 2024'!C:C,'Calculations 2'!A29,'Cleaned Data 2020 - 2024'!J:J) -> 50462.431 | E29: North America and ANZ | F29: 705690 | G29: 672480 | H29: =GETPIVOTDATA("Highest Happiness",$E$23,"Regional indicator","North America and ANZ")-GETPIVOTDATA("Lowest Happiness",$E$23,"Regional indicator","North America and ANZ") -> 33210
A30: North America and ANZ | B30: =AVERAGEIF('Cleaned Data 2020 - 2024'!C:C,'Calculations 2'!A30,'Cleaned Data 2020 - 2024'!J:J) -> 47932.1 | E30: South Asia | F30: 515840 | G30: 172100 | H30: =GETPIVOTDATA("Highest Happiness",$E$23,"Regional indicator","South Asia")-GETPIVOTDATA("Lowest Happiness",$E$23,"Regional indicator","South Asia") -> 343740
A31: Middle East and North Africa | B31: =AVERAGEIF('Cleaned Data 2020 - 2024'!C:C,'Calculations 2'!A31,'Cleaned Data 2020 - 2024'!J:J) -> 56931.133 | E31: Southeast Asia | F31: 652280 | G31: 434070 | H31: =GETPIVOTDATA("Highest Happiness",$E$23,"Regional indicator","Southeast Asia")-GETPIVOTDATA("Lowest Happiness",$E$23,"Regional indicator","Southeast Asia") -> 218210
A32: Latin America and Caribbean | B32: =AVERAGEIF('Cleaned Data 2020 - 2024'!C:C,'Calculations 2'!A32,'Cleaned Data 2020 - 2024'!J:J) -> 57916 | E32: Sub-Saharan Africa | F32: 581640 | G32: 318620 | H32: =GETPIVOTDATA("Highest Happiness",$E$23,"Regional indicator","Sub-Saharan Africa")-GETPIVOTDATA("Lowest Happiness",$E$23,"Regional indicator","Sub-Saharan Africa") -> 263020
A33: Central and Eastern Europe | B33: =AVERAGEIF('Cleaned Data 2020 - 2024'!C:C,'Calculations 2'!A33,'Cleaned Data 2020 - 2024'!J:J) -> 62063.321 | E33: Western Europe | F33: 774070 | G33: 602960 | H33: =GETPIVOTDATA("Highest Happiness",$E$23,"Regional indicator","Western Europe")-GETPIVOTDATA("Lowest Happiness",$E$23,"Regional indicator","Western Europe") -> 171110
A34: East Asia | B34: =AVERAGEIF('Cleaned Data 2020 - 2024'!C:C,'Calculations 2'!A34,'Cleaned Data 2020 - 2024'!J:J) -> 55582.25 | E34: Grand Total | F34: 774070 | G34: 172100 | H34: =SUM(H24:H33) -> 2040190
A35: Southeast Asia | B35: =AVERAGEIF('Cleaned Data 2020 - 2024'!C:C,'Calculations 2'!A35,'Cleaned Data 2020 - 2024'!J:J) -> 63178.805
A36: Commonwealth of Independent States | B36: =AVERAGEIF('Cleaned Data 2020 - 2024'!C:C,'Calculations 2'!A36,'Cleaned Data 2020 - 2024'!J:J) -> 55808.02
A37: Sub-Saharan Africa | B37: =AVERAGEIF('Cleaned Data 2020 - 2024'!C:C,'Calculations 2'!A37,'Cleaned Data 2020 - 2024'!J:J) -> 56684.903
A38: South Asia | B38: =AVERAGEIF('Cleaned Data 2020 - 2024'!C:C,'Calculations 2'!A38,'Cleaned Data 2020 - 2024'!J:J) -> 56274.867
A41: Regional indicator | B41: Top Country (Business Indicator)
A42: Western Europe | B42: =_xlfn.XLOOKUP(_xlfn.MAXIFS('Cleaned Data 2020 - 2024'!L:L,'Cleaned Data 2020 - 2024'!C:C,'Calculations 2'!A42),'Cleaned Data 2020 - 2024'!L:L,'Cleaned Data 2020 - 2024'!B:B) -> Luxembourg
A43: North America and ANZ | B43: =_xlfn.XLOOKUP(_xlfn.MAXIFS('Cleaned Data 2020 - 2024'!L:L,'Cleaned Data 2020 - 2024'!C:C,'Calculations 2'!A43),'Cleaned Data 2020 - 2024'!L:L,'Cleaned Data 2020 - 2024'!B:B) -> United States
A44: Middle East and North Africa | B44: =_xlfn.XLOOKUP(_xlfn.MAXIFS('Cleaned Data 2020 - 2024'!L:L,'Cleaned Data 2020 - 2024'!C:C,'Calculations 2'!A44),'Cleaned Data 2020 - 2024'!L:L,'Cleaned Data 2020 - 2024'!B:B) -> United Arab Emirates
A45: Latin America and Caribbean | B45: =_xlfn.XLOOKUP(_xlfn.MAXIFS('Cleaned Data 2020 - 2024'!L:L,'Cleaned Data 2020 - 2024'!C:C,'Calculations 2'!A45),'Cleaned Data 2020 - 2024'!L:L,'Cleaned Data 2020 - 2024'!B:B) -> Panama
...
